Mon Jul 08 02:33:02 CST 2019 : Apache Derby Network Server - 10.11.1.2 - (1629631) started and ready to accept connections on port 1527
----------------------------------------------------------------
Mon Jul 08 02:33:03 CST 2019:
Booting Derby version The Apache Software Foundation - Apache Derby - 10.11.1.2 - (1629631): instance a816c00e-016b-cdb5-cef9-ffffa54afd53 
on database directory C:\Users\Lorenz\Documents\GitHub\RR_pronounciation\rrDB with class loader sun.misc.Launcher$AppClassLoader@6f94fa3e 
Loaded from file:/C:/Program%20Files/Java/jdk1.8.0_111/db/lib/derby.jar
java.vendor=Oracle Corporation
java.runtime.version=1.8.0_111-b14
user.dir=C:\Program Files\Java\jdk1.8.0_111\db
os.name=Windows 10
os.arch=amd64
os.version=10.0
derby.system.home=C:\Users\Lorenz\Documents\GitHub\RR_pronounciation
Database Class Loader started - derby.database.classpath=''
Mon Jul 08 02:33:03 CST 2019 Thread[DRDAConnThread_2,5,main] (XID = 2808), (SESSIONID = 0), (DATABASE = rrDB), (DRDAID = {1}), Cleanup action starting
java.sql.SQLNonTransientConnectionException: Connection authentication failure occurred.  Reason: Invalid authentication..
	at org.apache.derby.impl.jdbc.SQLExceptionFactory.getSQLException(Unknown Source)
	at org.apache.derby.impl.jdbc.SQLExceptionFactory.getSQLException(Unknown Source)
	at org.apache.derby.impl.jdbc.Util.generateCsSQLException(Unknown Source)
	at org.apache.derby.impl.jdbc.Util.generateCsSQLException(Unknown Source)
	at org.apache.derby.impl.jdbc.EmbedConnection.newSQLException(Unknown Source)
	at org.apache.derby.impl.jdbc.EmbedConnection.checkUserCredentials(Unknown Source)
	at org.apache.derby.impl.jdbc.EmbedConnection.<init>(Unknown Source)
	at org.apache.derby.jdbc.InternalDriver.getNewEmbedConnection(Unknown Source)
	at org.apache.derby.jdbc.InternalDriver.connect(Unknown Source)
	at org.apache.derby.jdbc.InternalDriver.connect(Unknown Source)
	at org.apache.derby.jdbc.EmbeddedDriver.connect(Unknown Source)
	at org.apache.derby.impl.drda.Database.makeConnection(Unknown Source)
	at org.apache.derby.impl.drda.DRDAConnThread.getConnFromDatabaseName(Unknown Source)
	at org.apache.derby.impl.drda.DRDAConnThread.verifyUserIdPassword(Unknown Source)
	at org.apache.derby.impl.drda.DRDAConnThread.parseSECCHK(Unknown Source)
	at org.apache.derby.impl.drda.DRDAConnThread.parseDRDAConnection(Unknown Source)
	at org.apache.derby.impl.drda.DRDAConnThread.processCommands(Unknown Source)
	at org.apache.derby.impl.drda.DRDAConnThread.run(Unknown Source)
Caused by: ERROR 08004: Connection authentication failure occurred.  Reason: Invalid authentication..
	at org.apache.derby.iapi.error.StandardException.newException(Unknown Source)
	at org.apache.derby.impl.jdbc.SQLExceptionFactory.wrapArgsForTransportAcrossDRDA(Unknown Source)
	... 18 more
============= begin nested exception, level (1) ===========
ERROR 08004: Connection authentication failure occurred.  Reason: Invalid authentication..
	at org.apache.derby.iapi.error.StandardException.newException(Unknown Source)
	at org.apache.derby.impl.jdbc.SQLExceptionFactory.wrapArgsForTransportAcrossDRDA(Unknown Source)
	at org.apache.derby.impl.jdbc.SQLExceptionFactory.getSQLException(Unknown Source)
	at org.apache.derby.impl.jdbc.SQLExceptionFactory.getSQLException(Unknown Source)
	at org.apache.derby.impl.jdbc.Util.generateCsSQLException(Unknown Source)
	at org.apache.derby.impl.jdbc.Util.generateCsSQLException(Unknown Source)
	at org.apache.derby.impl.jdbc.EmbedConnection.newSQLException(Unknown Source)
	at org.apache.derby.impl.jdbc.EmbedConnection.checkUserCredentials(Unknown Source)
	at org.apache.derby.impl.jdbc.EmbedConnection.<init>(Unknown Source)
	at org.apache.derby.jdbc.InternalDriver.getNewEmbedConnection(Unknown Source)
	at org.apache.derby.jdbc.InternalDriver.connect(Unknown Source)
	at org.apache.derby.jdbc.InternalDriver.connect(Unknown Source)
	at org.apache.derby.jdbc.EmbeddedDriver.connect(Unknown Source)
	at org.apache.derby.impl.drda.Database.makeConnection(Unknown Source)
	at org.apache.derby.impl.drda.DRDAConnThread.getConnFromDatabaseName(Unknown Source)
	at org.apache.derby.impl.drda.DRDAConnThread.verifyUserIdPassword(Unknown Source)
	at org.apache.derby.impl.drda.DRDAConnThread.parseSECCHK(Unknown Source)
	at org.apache.derby.impl.drda.DRDAConnThread.parseDRDAConnection(Unknown Source)
	at org.apache.derby.impl.drda.DRDAConnThread.processCommands(Unknown Source)
	at org.apache.derby.impl.drda.DRDAConnThread.run(Unknown Source)
============= end nested exception, level (1) ===========
Cleanup action completed
Mon Jul 08 02:33:03 CST 2019 Thread[DRDAConnThread_2,5,main] (DATABASE = rrDB), (DRDAID = {1}), Connection authentication failure occurred.  Reason: Invalid authentication..
Mon Jul 08 02:33:30 CST 2019 Thread[DRDAConnThread_2,5,main] (XID = 2809), (SESSIONID = 1), (DATABASE = rrDB), (DRDAID = {2}), Cleanup action starting
java.sql.SQLNonTransientConnectionException: Connection authentication failure occurred.  Reason: Invalid authentication..
	at org.apache.derby.impl.jdbc.SQLExceptionFactory.getSQLException(Unknown Source)
	at org.apache.derby.impl.jdbc.SQLExceptionFactory.getSQLException(Unknown Source)
	at org.apache.derby.impl.jdbc.Util.generateCsSQLException(Unknown Source)
	at org.apache.derby.impl.jdbc.Util.generateCsSQLException(Unknown Source)
	at org.apache.derby.impl.jdbc.EmbedConnection.newSQLException(Unknown Source)
	at org.apache.derby.impl.jdbc.EmbedConnection.checkUserCredentials(Unknown Source)
	at org.apache.derby.impl.jdbc.EmbedConnection.<init>(Unknown Source)
	at org.apache.derby.jdbc.InternalDriver.getNewEmbedConnection(Unknown Source)
	at org.apache.derby.jdbc.InternalDriver.connect(Unknown Source)
	at org.apache.derby.jdbc.InternalDriver.connect(Unknown Source)
	at org.apache.derby.jdbc.EmbeddedDriver.connect(Unknown Source)
	at org.apache.derby.impl.drda.Database.makeConnection(Unknown Source)
	at org.apache.derby.impl.drda.DRDAConnThread.getConnFromDatabaseName(Unknown Source)
	at org.apache.derby.impl.drda.DRDAConnThread.verifyUserIdPassword(Unknown Source)
	at org.apache.derby.impl.drda.DRDAConnThread.parseSECCHK(Unknown Source)
	at org.apache.derby.impl.drda.DRDAConnThread.parseDRDAConnection(Unknown Source)
	at org.apache.derby.impl.drda.DRDAConnThread.processCommands(Unknown Source)
	at org.apache.derby.impl.drda.DRDAConnThread.run(Unknown Source)
Caused by: ERROR 08004: Connection authentication failure occurred.  Reason: Invalid authentication..
	at org.apache.derby.iapi.error.StandardException.newException(Unknown Source)
	at org.apache.derby.impl.jdbc.SQLExceptionFactory.wrapArgsForTransportAcrossDRDA(Unknown Source)
	... 18 more
============= begin nested exception, level (1) ===========
ERROR 08004: Connection authentication failure occurred.  Reason: Invalid authentication..
	at org.apache.derby.iapi.error.StandardException.newException(Unknown Source)
	at org.apache.derby.impl.jdbc.SQLExceptionFactory.wrapArgsForTransportAcrossDRDA(Unknown Source)
	at org.apache.derby.impl.jdbc.SQLExceptionFactory.getSQLException(Unknown Source)
	at org.apache.derby.impl.jdbc.SQLExceptionFactory.getSQLException(Unknown Source)
	at org.apache.derby.impl.jdbc.Util.generateCsSQLException(Unknown Source)
	at org.apache.derby.impl.jdbc.Util.generateCsSQLException(Unknown Source)
	at org.apache.derby.impl.jdbc.EmbedConnection.newSQLException(Unknown Source)
	at org.apache.derby.impl.jdbc.EmbedConnection.checkUserCredentials(Unknown Source)
	at org.apache.derby.impl.jdbc.EmbedConnection.<init>(Unknown Source)
	at org.apache.derby.jdbc.InternalDriver.getNewEmbedConnection(Unknown Source)
	at org.apache.derby.jdbc.InternalDriver.connect(Unknown Source)
	at org.apache.derby.jdbc.InternalDriver.connect(Unknown Source)
	at org.apache.derby.jdbc.EmbeddedDriver.connect(Unknown Source)
	at org.apache.derby.impl.drda.Database.makeConnection(Unknown Source)
	at org.apache.derby.impl.drda.DRDAConnThread.getConnFromDatabaseName(Unknown Source)
	at org.apache.derby.impl.drda.DRDAConnThread.verifyUserIdPassword(Unknown Source)
	at org.apache.derby.impl.drda.DRDAConnThread.parseSECCHK(Unknown Source)
	at org.apache.derby.impl.drda.DRDAConnThread.parseDRDAConnection(Unknown Source)
	at org.apache.derby.impl.drda.DRDAConnThread.processCommands(Unknown Source)
	at org.apache.derby.impl.drda.DRDAConnThread.run(Unknown Source)
============= end nested exception, level (1) ===========
Cleanup action completed
Mon Jul 08 02:33:30 CST 2019 Thread[DRDAConnThread_2,5,main] (DATABASE = rrDB), (DRDAID = {2}), Connection authentication failure occurred.  Reason: Invalid authentication..
Mon Jul 08 02:34:01 CST 2019 Thread[DRDAConnThread_2,5,main] (XID = 2810), (SESSIONID = 2), (DATABASE = rrDB), (DRDAID = {3}), Cleanup action starting
java.sql.SQLNonTransientConnectionException: Connection authentication failure occurred.  Reason: Invalid authentication..
	at org.apache.derby.impl.jdbc.SQLExceptionFactory.getSQLException(Unknown Source)
	at org.apache.derby.impl.jdbc.SQLExceptionFactory.getSQLException(Unknown Source)
	at org.apache.derby.impl.jdbc.Util.generateCsSQLException(Unknown Source)
	at org.apache.derby.impl.jdbc.Util.generateCsSQLException(Unknown Source)
	at org.apache.derby.impl.jdbc.EmbedConnection.newSQLException(Unknown Source)
	at org.apache.derby.impl.jdbc.EmbedConnection.checkUserCredentials(Unknown Source)
	at org.apache.derby.impl.jdbc.EmbedConnection.<init>(Unknown Source)
	at org.apache.derby.jdbc.InternalDriver.getNewEmbedConnection(Unknown Source)
	at org.apache.derby.jdbc.InternalDriver.connect(Unknown Source)
	at org.apache.derby.jdbc.InternalDriver.connect(Unknown Source)
	at org.apache.derby.jdbc.EmbeddedDriver.connect(Unknown Source)
	at org.apache.derby.impl.drda.Database.makeConnection(Unknown Source)
	at org.apache.derby.impl.drda.DRDAConnThread.getConnFromDatabaseName(Unknown Source)
	at org.apache.derby.impl.drda.DRDAConnThread.verifyUserIdPassword(Unknown Source)
	at org.apache.derby.impl.drda.DRDAConnThread.parseSECCHK(Unknown Source)
	at org.apache.derby.impl.drda.DRDAConnThread.parseDRDAConnection(Unknown Source)
	at org.apache.derby.impl.drda.DRDAConnThread.processCommands(Unknown Source)
	at org.apache.derby.impl.drda.DRDAConnThread.run(Unknown Source)
Caused by: ERROR 08004: Connection authentication failure occurred.  Reason: Invalid authentication..
	at org.apache.derby.iapi.error.StandardException.newException(Unknown Source)
	at org.apache.derby.impl.jdbc.SQLExceptionFactory.wrapArgsForTransportAcrossDRDA(Unknown Source)
	... 18 more
============= begin nested exception, level (1) ===========
ERROR 08004: Connection authentication failure occurred.  Reason: Invalid authentication..
	at org.apache.derby.iapi.error.StandardException.newException(Unknown Source)
	at org.apache.derby.impl.jdbc.SQLExceptionFactory.wrapArgsForTransportAcrossDRDA(Unknown Source)
	at org.apache.derby.impl.jdbc.SQLExceptionFactory.getSQLException(Unknown Source)
	at org.apache.derby.impl.jdbc.SQLExceptionFactory.getSQLException(Unknown Source)
	at org.apache.derby.impl.jdbc.Util.generateCsSQLException(Unknown Source)
	at org.apache.derby.impl.jdbc.Util.generateCsSQLException(Unknown Source)
	at org.apache.derby.impl.jdbc.EmbedConnection.newSQLException(Unknown Source)
	at org.apache.derby.impl.jdbc.EmbedConnection.checkUserCredentials(Unknown Source)
	at org.apache.derby.impl.jdbc.EmbedConnection.<init>(Unknown Source)
	at org.apache.derby.jdbc.InternalDriver.getNewEmbedConnection(Unknown Source)
	at org.apache.derby.jdbc.InternalDriver.connect(Unknown Source)
	at org.apache.derby.jdbc.InternalDriver.connect(Unknown Source)
	at org.apache.derby.jdbc.EmbeddedDriver.connect(Unknown Source)
	at org.apache.derby.impl.drda.Database.makeConnection(Unknown Source)
	at org.apache.derby.impl.drda.DRDAConnThread.getConnFromDatabaseName(Unknown Source)
	at org.apache.derby.impl.drda.DRDAConnThread.verifyUserIdPassword(Unknown Source)
	at org.apache.derby.impl.drda.DRDAConnThread.parseSECCHK(Unknown Source)
	at org.apache.derby.impl.drda.DRDAConnThread.parseDRDAConnection(Unknown Source)
	at org.apache.derby.impl.drda.DRDAConnThread.processCommands(Unknown Source)
	at org.apache.derby.impl.drda.DRDAConnThread.run(Unknown Source)
============= end nested exception, level (1) ===========
Cleanup action completed
Mon Jul 08 02:34:01 CST 2019 Thread[DRDAConnThread_2,5,main] (DATABASE = rrDB), (DRDAID = {3}), Connection authentication failure occurred.  Reason: Invalid authentication..
